[2018-11-03 19:50:41,705] ERROR: Invalid ip or unknown error connecting to 192.168.1.50.
Traceback (most recent call last):
  File "/home/pi/oprint/local/lib/python2.7/site-packages/octoprint_tasmota/__init__.py", line 143, in check_status
    webresponse = urllib2.urlopen("http://" + plugip + "/cm?user=" + username + "&password=" + password + "&cmnd=Power" + str(plugidx)).read()
  File "/usr/lib/python2.7/urllib2.py", line 154, in urlopen
    return opener.open(url, data, timeout)
  File "/usr/lib/python2.7/urllib2.py", line 429, in open
    response = self._open(req, data)
  File "/usr/lib/python2.7/urllib2.py", line 447, in _open
    '_open', req)
  File "/usr/lib/python2.7/urllib2.py", line 407, in _call_chain
    result = func(*args)
  File "/usr/lib/python2.7/urllib2.py", line 1228, in http_open
    return self.do_open(httplib.HTTPConnection, req)
  File "/usr/lib/python2.7/urllib2.py", line 1198, in do_open
    raise URLError(err)
URLError: <urlopen error [Errno 113] No route to host>
